<?xml version='1.0'?>

<robot name="my_robot" xmlns:xacro="http://www.ros.org/wiki/xacro">

  <xacro:include filename="$(find my_robot)/urdf/my_robot.gazebo" />

  <link name="robot_footprint"></link>

  <joint name="robot_footprint_joint" type="fixed">
    <origin xyz="0 0 0" rpy="0 0 0" />
    <parent link="robot_footprint"/>
    <child link="chassis" />
  </joint>

  <link name='chassis'>
    <pose>0 0 0.3 0 0 0</pose>

    <inertial>
      <mass value="15.0"/>
      <origin xyz="0.0 0 0" rpy=" 0 0 0"/>
      <inertia
          ixx="0.1" ixy="0" ixz="0"
          iyy="0.1" iyz="0"
          izz="0.1"
      />
    </inertial>

    <collision name='collision'>
      <origin xyz="0 0 0" rpy=" 0 0 0"/> 
      <geometry>
        <box size=".8 .6 .3"/>
      </geometry>
    </collision>

    <visual name='chassis_visual'>
      <origin xyz="0 0 0" rpy=" 0 0 0"/>
      <geometry>
        <box size=".8 .6 .3"/>
      </geometry>
    </visual>

    <collision name='back_caster_collision'>
      <origin xyz="-0.3 0 -0.2" rpy=" 0 0 0"/>
      <geometry>
        <sphere radius="0.099"/>
      </geometry>
    </collision>

    <visual name='back_caster_visual'>
      <origin xyz="-0.3 0 -0.2" rpy=" 0 0 0"/>
      <geometry>
        <sphere radius="0.1"/>
      </geometry>
    </visual>

    <collision name='front_caster_collision'>
      <origin xyz="0.3 0 -0.2" rpy=" 0 0 0"/>
      <geometry>
        <sphere radius="0.099"/>
      </geometry>
    </collision>

    <visual name='front_caster_visual'>
      <origin xyz="0.3 0 -0.2" rpy=" 0 0 0"/>
      <geometry>
        <sphere radius="0.1"/>
      </geometry>
    </visual>

  </link>

  <!-- 2. Wheels -->
  <!-- left wheel -->
  <link name='left_wheel'>
    <collision>
      <origin xyz="0 0 0" rpy="0 1.5707 1.5707"/>
      <geometry>
        <cylinder radius="0.2" length="0.04"/>
      </geometry>
    </collision>
    <visual>
      <origin xyz="0 0 0" rpy="0 1.5707 1.5707"/>
      <geometry>
        <cylinder radius="0.2" length="0.04"/>
      </geometry>
    </visual>
    <inertial>
      <origin xyz="0 0 0" rpy="0 1.5707 1.5707"/>
      <mass value="5"/>
      <inertia
          ixx="0.1" ixy="0" ixz="0"
          iyy="0.1" iyz="0"
          izz="0.1"/>
    </inertial>
  </link>

  <gazebo reference="left_wheel">
    <material>Gazebo/Black</material>
  </gazebo>

  <joint type="continuous" name="left_wheel_hinge">
    <origin xyz="0 0.35 -0.1" rpy="0 0 0"/>
    <parent link="chassis"/>
    <child link="left_wheel"/>
    <axis xyz="0 1 0" rpy="0 0 0"/>
    <limit effort="10000" velocity="1000"/>
    <dynamics damping="1.0" friction="1.0"/>
  </joint>

  <!-- right wheel -->
  <link name='right_wheel'>
    <collision>
      <origin xyz="0 0 0" rpy="0 1.5707 1.5707"/>
      <geometry>
        <cylinder radius="0.2" length="0.04"/>
      </geometry>
    </collision>
    <visual>
      <origin xyz="0 0 0" rpy="0 1.5707 1.5707"/>
      <geometry>
        <cylinder radius="0.2" length="0.04"/>
      </geometry>
    </visual>
    <inertial>
      <origin xyz="0 0 0" rpy="0 1.5707 1.5707"/>
      <mass value="5"/>
      <inertia
          ixx="0.1" ixy="0" ixz="0"
          iyy="0.1" iyz="0"
          izz="0.1"/>
    </inertial>
  </link>

  <gazebo reference="right_wheel">
    <material>Gazebo/Black</material>
  </gazebo>

  <joint type="continuous" name="right_wheel_hinge">
    <origin xyz="0 -0.35 -0.1" rpy="0 0 0"/>
    <parent link="chassis"/>
    <child link="right_wheel"/>
    <axis xyz="0 1 0" rpy="0 0 0"/>
    <limit effort="10000" velocity="1000"/>
    <dynamics damping="1.0" friction="1.0"/>
  </joint>

  <!-- 3. Sensors -->
  <!-- camera -->
  <link name='camera'>
    <collision>
      <origin xyz="0 0 0" rpy="0 0 0"/>
      <geometry>
        <box size="0.05 0.05 0.05"/>
      </geometry>
    </collision>
    <visual>
      <origin xyz="0 0 0" rpy="0 0 0"/>
      <geometry>
        <box size="0.05 0.05 0.05"/>
      </geometry>
    </visual>
    <inertial>
      <origin xyz="0 0 0" rpy="0 0 0"/>
      <mass value="0.1"/>
      <inertia
          ixx="1e-6" ixy="0" ixz="0"
          iyy="1e-6" iyz="0"
          izz="1e-6"/>
    </inertial>
  </link>

  <gazebo reference="camera">
    <material>Gazebo/Gray</material>
  </gazebo>

  <joint type="fixed" name="camera_joint">
    <origin xyz="0.5 0 0" rpy="0 0 0"/>
    <parent link="chassis"/>
    <child link="camera"/>
  </joint>

  <!-- lidar -->
  <link name='hokuyo'>
    <collision>
      <origin xyz="0 0 0" rpy="0 0 0"/>
      <geometry>
        <box size="0.1 0.1 0.1"/>
      </geometry>
    </collision>
    <visual>
      <origin xyz="0 0 0" rpy="0 0 0"/>
      <geometry>
        <mesh filename="package://my_robot/meshes/hokuyo.dae"/>
      </geometry>
    </visual>
    <inertial>
      <origin xyz="0 0 0" rpy="0 0 0"/>
      <mass value="1e-5"/>
      <inertia
          ixx="1e-6" ixy="0" ixz="0"
          iyy="1e-6" iyz="0"
          izz="1e-6"/>
    </inertial>
  </link>

  <joint type="fixed" name="hokuyo_joint">
    <origin xyz="0 0 0.3" rpy="0 0 0"/>
    <parent link="chassis"/>
    <child link="hokuyo"/>
  </joint>

</robot>
